<?xml version="1.0" ?>
<robot name="demo">
  <!-- ======================================================== -->
  <!-- link -->
  <!-- ======================================================== -->
  <link name="base_link"/>
  <link name="demo_link">
    <inertial>
      <origin rpy="0.000000 0.000000 0.000000" xyz="0.000000 0.000000 0.002689"/>
      <mass value="9.815083"/>
      <inertia 
        ixx=" 0.337668" 
        iyy=" 0.337668" 
        izz=" 0.612925" 
        ixy=" 0.000000" 
        ixz=" 0.000000"  
        iyz=" 0.000000"/>
    </inertial>
    <visual>
      <origin rpy="0.000000 0.000000 0.000000" xyz="0.000000 0.000000 0.000000"/>
      <geometry>
        <mesh filename="package://urdf_demo/meshes/demo_link.STL"/>
      </geometry>
      <material name="">
        <color rgba="1 1 1 1"/>
      </material>
    </visual>
  </link>
  <!-- ======================================================== -->
  <!-- joint -->
  <!-- ======================================================== -->
  <joint name="my_joint" type="continuous">
    <origin xyz="0 0 0" rpy="0 0 0"/>
    <parent link="base_link"/>
    <child link="demo_link"/>
    <axis xyz="0 0 1" />
  </joint>
</robot>
